<?xml version="1.0"?>
<sdf version="1.6">
  <model name="mobile_robot">
    <link name="base_link">
      <inertial>
        <mass>35.633</mass>
        <pose>-5.6012E-06 -2.2204E-16 0.042753 0 0 0</pose>
        <inertia>
          <ixx>1.8217</ixx>
          <ixy>-9.2827E-16</ixy>
          <ixz>-1.2537E-05</ixz>
          <iyy>4.1378</iyy>
          <iyz>-4.2401E-15</iyz>
          <izz>5.2895</izz>
        </inertia>
      </inertial>
      <visual name="base_link_visual">
        <geometry>
          <mesh>
            <uri>package://mobile_robot/meshes/base_link.STL</uri>
          </mesh>
        </geometry>
        <material>
          <ambient>0.79216 0.81961 0.93333 1</ambient>
          <diffuse>0.79216 0.81961 0.93333 1</diffuse>
        </material>
      </visual>
      <collision name="base_link_collision">
        <geometry>
          <mesh>
            <uri>package://mobile_robot/meshes/base_link.STL</uri>
          </mesh>
        </geometry>
        <surface>
          <friction>
            <ode>
              <mu>0.2</mu>
              <mu2>0.2</mu2>
            </ode>
          </friction>
        </surface>
      </collision>
    </link>

    <link name="leftWheeltLink">
      <pose>0 0.325 0.0375 1.5708 0 0</pose>
      <inertial>
        <mass>9.0457</mass>
        <inertia>
          <ixx>0.063134</ixx>
          <ixy>-2.9772E-11</ixy>
          <ixz>-7.331E-14</ixz>
          <iyy>0.063134</iyy>
          <iyz>1.2811E-14</iyz>
          <izz>0.12097</izz>
        </inertia>
      </inertial>
      <visual name="leftWheeltLink_visual">
        <geometry>
          <mesh>
            <uri>package://mobile_robot/meshes/leftWheeltLink.STL</uri>
          </mesh>
        </geometry>
        <material>
          <ambient>0.2 0.2 0.2 1</ambient>
          <diffuse>0.2 0.2 0.2 1</diffuse>
        </material>
      </visual>
      <collision name="leftWheeltLink_collision">
        <geometry>
          <mesh>
            <uri>package://mobile_robot/meshes/leftWheeltLink.STL</uri>
          </mesh>
        </geometry>
        <surface>
          <friction>
            <ode>
              <mu>0.5</mu>
              <mu2>0.5</mu2>
            </ode>
          </friction>
        </surface>
      </collision>
    </link>

    <joint name="leftWheelJoint" type="revolute">
      <parent>base_link</parent>
      <child>leftWheeltLink</child>
      <axis>
        <xyz>0 0 -1</xyz>
        <limit>
          <effort>100</effort>
          <velocity>100</velocity>
        </limit>
        <dynamics>
          <friction>1</friction>
        </dynamics>
      </axis>
    </joint>

    <link name="rightWheelLink">
      <pose>0 -0.325 0.0375 1.5708 0 0</pose>
      <inertial>
        <mass>9.0457</mass>
        <inertia>
          <ixx>0.063134</ixx>
          <ixy>-2.941E-11</ixy>
          <ixz>2.9021E-14</ixz>
          <iyy>0.063134</iyy>
          <iyz>-6.8537E-14</iyz>
          <izz>0.12097</izz>
        </inertia>
      </inertial>
      <visual name="rightWheelLink_visual">
        <geometry>
          <mesh>
            <uri>package://mobile_robot/meshes/rightWheelLink.STL</uri>
          </mesh>
        </geometry>
        <material>
          <ambient>0.2 0.2 0.2 1</ambient>
          <diffuse>0.2 0.2 0.2 1</diffuse>
        </material>
      </visual>
      <collision name="rightWheelLink_collision">
        <geometry>
          <mesh>
            <uri>package://mobile_robot/meshes/rightWheelLink.STL</uri>
          </mesh>
        </geometry>
        <surface>
          <friction>
            <ode>
              <mu>0.5</mu>
              <mu2>0.5</mu2>
            </ode>
          </friction>
        </surface>
      </collision>
    </link>

    <joint name="rightWheelJoint" type="revolute">
      <parent>base_link</parent>
      <child>rightWheelLink</child>
      <axis>
        <xyz>0 0 1</xyz>
        <limit>
          <effort>100</effort>
          <velocity>100</velocity>
        </limit>
        <dynamics>
          <friction>1</friction>
        </dynamics>
      </axis>
    </joint>

  </model>
</sdf>